<?xml version="1.0" encoding="utf-8"?>
<!-- =================================================================================== -->
<!-- |    This document was autogenerated by xacro from spot/src/myrobot/urdf/thespot.urdf.xacro | -->
<!-- |    EDITING THIS FILE BY HAND IS NOT RECOMMENDED                                 | -->
<!-- =================================================================================== -->
<robot name="thespot_robot" xmlns:xacro="http://www.ros.org/wiki/xacro">
  <static>true</static>
  <link name="world"/>
  <joint name="fixed" type="fixed">
    <parent link="world"/>
    <child link="body"/>
  </joint>
  <link name="body">
    <visual>
      <origin rpy="0 0 0" xyz="0 0 0.2"/>
      <geometry>
        <box size="0.4 0.2 0.1"/>
      </geometry>
      <material name="Cyan">
        <color rgba="0 1.0 1.0 1.0"/>
      </material>
    </visual>
    <inertial>
      <mass value="5"/>
      <inertia ixx="0.4" ixy="0.0" ixz="0.0" iyy="0.4" iyz="0.0" izz="0.2"/>
    </inertial>
    <collision>
      <geometry>
        <box size="0.4 0.2 0.1"/>
      </geometry>
    </collision>
  </link>
  <link name="left_back_big_leg">
    <visual>
      <origin rpy="0 -0.7 0" xyz="-0.05 -0.05 -0.05"/>
      <geometry>
        <box size="0.2 0.03 0.03"/>
      </geometry>
      <material name="red">
        <color rgba="1.00 0 0 1.0"/>
      </material>
    </visual>
    <inertial>
      <mass value="10"/>
      <inertia ixx="0.4" ixy="0.0" ixz="0.0" iyy="0.4" iyz="0.0" izz="0.2"/>
    </inertial>
    <collision>
      <geometry>
        <box size="0.2 0.03 0.03"/>
      </geometry>
    </collision>
  </link>
  <joint name="body_to_left_back_big_leg" type="revolute">
    <origin rpy="0 0 0" xyz="-0.15 0.2 0.2"/>
    <parent link="body"/>
    <child link="left_back_big_leg"/>
    <axis xyz="0 1 0"/>
    <limit effort="30" lower="-2.2" upper="0.7" velocity="1.0"/>
  </joint>
  <link name="left_back_small_leg">
    <visual>
      <origin rpy="0 0.7 0" xyz="0.05 -0.05 -0.05"/>
      <geometry>
        <box size="0.2 0.03 0.03"/>
      </geometry>
      <material name="red">
        <color rgba="1.00 0 0 1.0"/>
      </material>
    </visual>
    <inertial>
      <mass value="10"/>
      <inertia ixx="0.4" ixy="0.0" ixz="0.0" iyy="0.4" iyz="0.0" izz="0.2"/>
    </inertial>
    <collision>
      <geometry>
        <box size="0.2 0.03 0.03"/>
      </geometry>
    </collision>
  </link>
  <joint name="left_back_big_leg_to_left_back_small_leg" type="revolute">
    <origin rpy="0 0 0" xyz="-0.13 0.055 -0.1"/>
    <parent link="left_back_big_leg"/>
    <child link="left_back_small_leg"/>
    <axis xyz="0 1 0"/>
    <limit effort="30" lower="-0.7" upper="0.7" velocity="1.0"/>
  </joint>
  <!-- A bunch of stuff cut -->
  <link name="right_back_big_leg">
    <visual>
      <origin rpy="0 -0.7 0" xyz="-0.05 -0.05 -0.05"/>
      <geometry>
        <box size="0.2 0.03 0.03"/>
      </geometry>
      <material name="red">
        <color rgba="1.00 0 0 1.0"/>
      </material>
    </visual>
    <inertial>
      <mass value="10"/>
      <inertia ixx="0.4" ixy="0.0" ixz="0.0" iyy="0.4" iyz="0.0" izz="0.2"/>
    </inertial>
    <collision>
      <geometry>
        <box size="0.2 0.03 0.03"/>
      </geometry>
    </collision>
  </link>
  <joint name="body_to_right_back_big_leg" type="revolute">
    <origin rpy="0 0 0" xyz="0.15 0.2 0.2"/>
    <parent link="body"/>
    <child link="right_back_big_leg"/>
    <axis xyz="0 1 0"/>
    <limit effort="30" lower="-2.2" upper="0.7" velocity="1.0"/>
  </joint>
  <link name="right_back_small_leg">
    <visual>
      <origin rpy="0 0.7 0" xyz="0.05 -0.05 -0.05"/>
      <geometry>
        <box size="0.2 0.03 0.03"/>
      </geometry>
      <material name="red">
        <color rgba="1.00 0 0 1.0"/>
      </material>
    </visual>
    <inertial>
      <mass value="10"/>
      <inertia ixx="0.4" ixy="0.0" ixz="0.0" iyy="0.4" iyz="0.0" izz="0.2"/>
    </inertial>
    <collision>
      <geometry>
        <box size="0.2 0.03 0.03"/>
      </geometry>
    </collision>
  </link>
  <joint name="right_back_big_leg_to_right_back_small_leg" type="revolute">
    <origin rpy="0 0 0" xyz="-0.15 0.055 -0.1"/>
    <parent link="right_back_big_leg"/>
    <child link="right_back_small_leg"/>
    <axis xyz="0 1 0"/>
    <limit effort="30" lower="-0.7" upper="0.7" velocity="1.0"/>
  </joint>
  <!-- A bunch of stuff cut -->
  <link name="right_forward_big_leg">
    <visual>
      <origin rpy="0 -0.7 0" xyz="-0.05 -0.05 -0.05"/>
      <geometry>
        <box size="0.2 0.03 0.03"/>
      </geometry>
      <material name="red">
        <color rgba="1.00 0 0 1.0"/>
      </material>
    </visual>
    <inertial>
      <mass value="10"/>
      <inertia ixx="0.4" ixy="0.0" ixz="0.0" iyy="0.4" iyz="0.0" izz="0.2"/>
    </inertial>
    <collision>
      <geometry>
        <box size="0.2 0.03 0.03"/>
      </geometry>
    </collision>
  </link>
  <joint name="body_to_right_forward_big_leg" type="revolute">
    <origin rpy="0 0 0" xyz="-0.15 -0.1 0.2"/>
    <parent link="body"/>
    <child link="right_forward_big_leg"/>
    <axis xyz="0 1 0"/>
    <limit effort="30" lower="-2.2" upper="0.7" velocity="1.0"/>
  </joint>
  <link name="right_forward_small_leg">
    <visual>
      <origin rpy="0 0.7 0" xyz="0.05 -0.05 -0.05"/>
      <geometry>
        <box size="0.2 0.03 0.03"/>
      </geometry>
      <material name="red">
        <color rgba="1.00 0 0 1.0"/>
      </material>
    </visual>
    <inertial>
      <mass value="10"/>
      <inertia ixx="0.4" ixy="0.0" ixz="0.0" iyy="0.4" iyz="0.0" izz="0.2"/>
    </inertial>
    <collision>
      <geometry>
        <box size="0.2 0.03 0.03"/>
      </geometry>
    </collision>
  </link>
  <joint name="right_forward_big_leg_to_right_forward_small_leg" type="revolute">
    <origin rpy="0 0 0" xyz="-0.15 -0.055 -0.1"/>
    <parent link="right_forward_big_leg"/>
    <child link="right_forward_small_leg"/>
    <axis xyz="0 1 0"/>
    <limit effort="30" lower="-0.7" upper="0.7" velocity="1.0"/>
  </joint>
  <!-- A bunch of stuff cut -->
  <link name="left_forward_big_leg">
    <visual>
      <origin rpy="0 -0.7 0" xyz="-0.05 -0.05 -0.05"/>
      <geometry>
        <box size="0.2 0.03 0.03"/>
      </geometry>
      <material name="red">
        <color rgba="1.00 0 0 1.0"/>
      </material>
    </visual>
    <inertial>
      <mass value="10"/>
      <inertia ixx="0.4" ixy="0.0" ixz="0.0" iyy="0.4" iyz="0.0" izz="0.2"/>
    </inertial>
    <collision>
      <geometry>
        <box size="0.2 0.03 0.03"/>
      </geometry>
    </collision>
  </link>
  <joint name="body_to_left_forward_big_leg" type="revolute">
    <origin rpy="0 0 0" xyz="0.15 -0.1 0.2"/>
    <parent link="body"/>
    <child link="left_forward_big_leg"/>
    <axis xyz="0 1 0"/>
    <limit effort="30" lower="-2.2" upper="0.7" velocity="1.0"/>
  </joint>
  <link name="left_forward_small_leg">
    <visual>
      <origin rpy="0 0.7 0" xyz="0.05 -0.05 -0.05"/>
      <geometry>
        <box size="0.2 0.03 0.03"/>
      </geometry>
      <material name="red">
        <color rgba="1.00 0 0 1.0"/>
      </material>
    </visual>
    <inertial>
      <mass value="10"/>
      <inertia ixx="0.4" ixy="0.0" ixz="0.0" iyy="0.4" iyz="0.0" izz="0.2"/>
    </inertial>
    <collision>
      <geometry>
        <box size="0.2 0.03 0.03"/>
      </geometry>
    </collision>
  </link>
  <joint name="left_forward_big_leg_to_left_forward_small_leg" type="revolute">
    <origin rpy="0 0 0" xyz="-0.15 -0.055 -0.1"/>
    <parent link="left_forward_big_leg"/>
    <child link="left_forward_small_leg"/>
    <axis xyz="0 1 0"/>
    <limit effort="30" lower="-0.7" upper="0.7" velocity="1.0"/>
  </joint>
  <!-- A bunch of stuff cut -->
  <gazebo>
    <plugin filename="libgazebo_ros_control.so" name="gazebo_ros_control">
      <robotNamespace>/thespot_robot</robotNamespace>
    </plugin>
  </gazebo>
  <transmission name="left_back_big">
    <type>transmission_interface/SimpleTransmission</type>
    <joint name="body_to_left_back_big_leg">
      <hardwareInterface>hardware_interface/EffortJointInterface</hardwareInterface>
    </joint>
    <actuator name="left_back_big">
      <hardwareInterface>hardware_interface/EffortJointInterface</hardwareInterface>
      <mechanicalReduction>1</mechanicalReduction>
    </actuator>
  </transmission>
  <transmission name="left_back_small">
    <type>transmission_interface/SimpleTransmission</type>
    <joint name="left_back_big_leg_to_left_back_small_leg">
      <hardwareInterface>hardware_interface/EffortJointInterface</hardwareInterface>
    </joint>
    <actuator name="left_back_small">
      <hardwareInterface>hardware_interface/EffortJointInterface</hardwareInterface>
      <mechanicalReduction>1</mechanicalReduction>
    </actuator>
  </transmission>
  <transmission name="right_back_big">
    <type>transmission_interface/SimpleTransmission</type>
    <joint name="body_to_right_back_big_leg">
      <hardwareInterface>hardware_interface/EffortJointInterface</hardwareInterface>
    </joint>
    <actuator name="right_back_big">
      <hardwareInterface>hardware_interface/EffortJointInterface</hardwareInterface>
      <mechanicalReduction>1</mechanicalReduction>
    </actuator>
  </transmission>
  <transmission name="right_back_small">
    <type>transmission_interface/SimpleTransmission</type>
    <joint name="right_back_big_leg_to_right_back_small_leg">
      <hardwareInterface>hardware_interface/EffortJointInterface</hardwareInterface>
    </joint>
    <actuator name="right_back_small">
      <hardwareInterface>hardware_interface/EffortJointInterface</hardwareInterface>
      <mechanicalReduction>1</mechanicalReduction>
    </actuator>
  </transmission>
  <transmission name="right_forward_big">
    <type>transmission_interface/SimpleTransmission</type>
    <joint name="body_to_right_forward_big_leg">
      <hardwareInterface>hardware_interface/EffortJointInterface</hardwareInterface>
    </joint>
    <actuator name="right_forward_big">
      <hardwareInterface>hardware_interface/EffortJointInterface</hardwareInterface>
      <mechanicalReduction>1</mechanicalReduction>
    </actuator>
  </transmission>
  <transmission name="right_forward_small">
    <type>transmission_interface/SimpleTransmission</type>
    <joint name="right_forward_big_leg_to_right_forward_small_leg">
      <hardwareInterface>hardware_interface/EffortJointInterface</hardwareInterface>
    </joint>
    <actuator name="right_forward_small">
      <hardwareInterface>hardware_interface/EffortJointInterface</hardwareInterface>
      <mechanicalReduction>1</mechanicalReduction>
    </actuator>
  </transmission>
  <transmission name="left_forward_big">
    <type>transmission_interface/SimpleTransmission</type>
    <joint name="body_to_left_forward_big_leg">
      <hardwareInterface>hardware_interface/EffortJointInterface</hardwareInterface>
    </joint>
    <actuator name="left_forward_big">
      <hardwareInterface>hardware_interface/EffortJointInterface</hardwareInterface>
      <mechanicalReduction>1</mechanicalReduction>
    </actuator>
  </transmission>
  <transmission name="left_forward_small">
    <type>transmission_interface/SimpleTransmission</type>
    <joint name="left_forward_big_leg_to_left_forward_small_leg">
      <hardwareInterface>hardware_interface/EffortJointInterface</hardwareInterface>
    </joint>
    <actuator name="left_forward_small">
      <hardwareInterface>hardware_interface/EffortJointInterface</hardwareInterface>
      <mechanicalReduction>1</mechanicalReduction>
    </actuator>
  </transmission>
</robot>

